Workbook

Sheet Requirement Overview
A1: Aging | B1: Type of Hire | C1: Job ID | D1: Job Posted Date | E1: Business Unit | F1: Department | G1: Client | H1: Domain | I1: Position | J1: Priority | K1: Number of Openings | L1: Position Current Status | M1: Remarks | N1: Candidate Concerned | O1: Date of Hold | P1: Date of Offer Stage | Q1: Date of Offer | R1: Date of Joining | S1: CTC of Candidate | T1: Source | U1: Harmonized Role | V1: Recruiter tagged | W1: Original Job Post Date
A2: =IF(OR(L2="Closed",L2="Offered"),Q2-D2,TODAY()-D2) -> 163 | B2: New | C2: A001 | D2: 45976 | E2: Talme | G2: EMIDS | H2: IT | I2: Python Developer | J2: High | K2: 2 | L2: Open
A3: =IF(OR(L3="Closed",L3="Offered"),Q3-D3,TODAY()-D3) -> 163 | B3: New | C3: A002 | D3: 45976 | E3: Talme | G3: EMIDS | H3: IT | I3: Lead Data Engineer | J3: High | K3: 4 | L3: Open
A4: =IF(OR(L4="Closed",L4="Offered"),Q4-D4,TODAY()-D4) -> 163 | B4: New | C4: A003 | D4: 45976 | E4: Talme | G4: EMIDS | H4: IT | I4: Python Architect | J4: High | K4: 1 | L4: Open
A5: =IF(OR(L5="Closed",L5="Offered"),Q5-D5,TODAY()-D5) -> 163 | B5: New | C5: A004 | D5: 45976 | E5: Talme | G5: EMIDS | H5: IT | I5: Windows system adminstrator | J5: High | K5: 1 | L5: Open
A6: =IF(OR(L6="Closed",L6="Offered"),Q6-D6,TODAY()-D6) -> 187 | B6: New | C6: B001 | D6: 45952 | E6: Talme | G6: KPIT | H6: IT | I6: Android BSP Developer | J6: High | K6: 2 | L6: Open
A7: =IF(OR(L7="Closed",L7="Offered"),Q7-D7,TODAY()-D7) -> 187 | B7: New | C7: B002 | D7: 45952 | E7: Talme | G7: KPIT | H7: IT | I7: Display driver | J7: High | K7: 1 | L7: Open
A8: =IF(OR(L8="Closed",L8="Offered"),Q8-D8,TODAY()-D8) -> 187 | B8: New | C8: B003 | D8: 45952 | E8: Talme | G8: KPIT | H8: IT | I8: Audio Driver | J8: High | K8: 1 | L8: Open
A9: =IF(OR(L9="Closed",L9="Offered"),Q9-D9,TODAY()-D9) -> 187 | B9: New | C9: C001 | D9: 45952 | E9: Talme | G9: Thoughtfocus | H9: IT | I9: Data Delivery Manager | J9: High | K9: 1 | L9: Open
A10: =IF(OR(L10="Closed",L10="Offered"),Q10-D10,TODAY()-D10) -> 187 | B10: New | C10: C002 | D10: 45952 | E10: Talme | G10: Thoughtfocus | H10: IT | I10: Senior IAM Operation Engineer | J10: High | K10: 1 | L10: Open
A11: =IF(OR(L11="Closed",L11="Offered"),Q11-D11,TODAY()-D11) -> 187 | B11: New | C11: C003 | D11: 45952 | E11: Talme | G11: Thoughtfocus | H11: IT | I11: Lead IAM Management | J11: High | K11: 1 | L11: Open
A12: =IF(OR(L12="Closed",L12="Offered"),Q12-D12,TODAY()-D12) -> 187 | B12: New | C12: C004 | D12: 45952 | E12: Talme | G12: Thoughtfocus | H12: IT | I12: PERL Developer | J12: Low | K12: 18 | L12: Hold
A13: =IF(OR(L13="Closed",L13="Offered"),Q13-D13,TODAY()-D13) -> 117 | B13: New | C13: D001 | D13: 46022 | E13: Talme | G13: Peritas | H13: Non - IT | I13: Inside Sales Executive | J13: High | K13: 3 | L13: Open
... A30: =IF(OR(L30="Closed",L30="Offered"),Q30-D30,TODAY()-D30) -> 98 | B30: New | C30: H006 | D30: 46041 | E30: Talme | G30: LeadSOC | H30: IT | I30: Analog RF Designer | J30: High | K30: 1 | L30: Open
A31: =IF(OR(L31="Closed",L31="Offered"),Q31-D31,TODAY()-D31) -> 14 | B31: New | C31: H007 | D31: 46016 | E31: Talme | G31: GNA | H31: IT | I31: Web Designer | J31: High | K31: 1 | L31: Closed | N31: Bhageesha | Q31: 46030 | R31: 46038 | S31: 3.58 LPA | T31: Portal-Naukri | V31: Harshitha
A32: =IF(OR(L32="Closed",L32="Offered"),Q32-D32,TODAY()-D32) -> 187 | B32: New | C32: H008 | D32: 45952 | E32: Talme | G32: Thoughtfocus | H32: IT | I32: IAM Engineer Professionals | J32: High | K32: 1 | L32: Open
A33: =IF(OR(L33="Closed",L33="Offered"),Q33-D33,TODAY()-D33) -> 289 | B33: New | C33: H009 | D33: 45850 | E33: Talme | G33: Semnox Solutions | H33: IT | I33: .Net Backend Developer | J33: High | K33: 1 | L33: Open
A34: =IF(OR(L34="Closed",L34="Offered"),Q34-D34,TODAY()-D34) -> 94 | B34: New | C34: H010 | D34: 46045 | E34: Talme | G34: Semnox Solutions | H34: IT | I34: Technical Lead - Mobile Development | J34: High | K34: 3 | L34: Open
A35: =IF(OR(L35="Closed",L35="Offered"),Q35-D35,TODAY()-D35) -> 94 | B35: New | C35: H011 | D35: 46045 | E35: Talme | G35: Prasanna Technologies | H35: IT | I35: .Net Developer - Contract Role | J35: High | K35: 1 | L35: Hold
A36: =IF(OR(L36="Closed",L36="Offered"),Q36-D36,TODAY()-D36) -> 93 | B36: New | C36: H012 | D36: 46046 | E36: Talme | G36: Viditha | H36: IT | I36: Developer - Angular & Node Js | J36: High | K36: 1 | L36: Open
A37: =IF(OR(L37="Closed",L37="Offered"),Q37-D37,TODAY()-D37) -> 90 | B37: New | C37: H013 | D37: 46049 | E37: Talme | G37: Thoughtfocus | H37: IT | I37: Java Lead Analyst | J37: High | K37: 1 | L37: Open
A38: =IF(OR(L38="Closed",L38="Offered"),Q38-D38,TODAY()-D38) -> 87 | B38: New | C38: H014 | D38: 46052 | E38: Talme | G38: EMIDS | H38: IT | I38: Java Script Developer | J38: High | K38: 1 | L38: Open
A39: =IF(OR(L39="Closed",L39="Offered"),Q39-D39,TODAY()-D39) -> 87 | B39: New | C39: I001 | D39: 46052 | E39: Talme | G39: GNA | H39: IT | I39: QA Analyst | J39: High | K39: 1 | L39: Open
A40: =IF(OR(L40="Closed",L40="Offered"),Q40-D40,TODAY()-D40) -> 87 | B40: New | C40: I002 | D40: 46052 | E40: Talme | G40: GNA | H40: IT | I40: Full Stack Developer | J40: High | K40: 1 | L40: Open
A41: =IF(OR(L41="Closed",L41="Offered"),Q41-D41,TODAY()-D41) -> 75 | B41: New | C41: I003 | D41: 46064 | E41: Talme | G41: Thoughtfocus | H41: IT | I41: Full Stack Developer | J41: High | K41: 3 | L41: Open
A42: =IF(OR(L42="Closed",L42="Offered"),Q42-D42,TODAY()-D42) -> 75 | B42: New | C42: I004 | D42: 46064 | E42: Talme | G42: Thoughtfocus | H42: IT | I42: Backend developer | J42: High | K42: 3 | L42: Open
A43: =IF(OR(L43="Closed",L43="Offered"),Q43-D43,TODAY()-D43) -> 75 | B43: New | C43: I005 | D43: 46064 | E43: Talme | G43: Thoughtfocus | H43: IT | I43: Front end developer | J43: High | K43: 3 | L43: Open
... A73: =IF(OR(L73="Closed",L73="Offered"),Q73-D73,TODAY()-D73) -> 20 | B73: New | C73: P001 | D73: 46119 | E73: Talme | G73: LTTS | H73: IT | I73: Software Engineer | J73: High | K73: 1 | L73: Open

Sheet Candidate Master
A1: Job Id | B1: Recruiter Id | C1: Recruiter Name | D1: Business Unit | E1: Domain | F1: Position | G1: Client | H1: Candidate Name | I1: Notice Period | J1: Candidate Email | K1: Phone No. | L1: Qualification | M1: Years of Exp | N1: Previous Company | O1: Previous CTC | P1: Location | Q1: Prefered Location | R1: Expected CTC | S1: Candidate Current Status | T1: Source | U1: Source Date | V1: Screening Date | W1: Screening Notes | X1: Tech 1 date | Y1: Tech 1 Status | Z1: Tech 1 Remarks | AA1: Tech 1 Panel | AB1: Tech 2 date | AC1: Tech 2 Status | AD1: Tech 2 Remarks | AE1: Tech 2 Panel | AF1: Tech 3 date | AG1: Tech 3 Status | AH1: Tech 3 Remarks | AI1: Tech 3 Panel | AJ1: Offer Stage Input date | AK1: Date of Document Collection | AL1: Date of Approval | AM1: Offer Date | AN1: Offer Status | AO1: Date of Offer Accept/Reject | AP1: Offer Accept Status | AQ1: Date Of Joining | AR1: Joining Status | AS1: CTC Offered
A2: B001 | B2: R004 | C2: Pooja | D2: =IF(ISBLANK(A2),"",_xlfn.XLOOKUP(A2,'Requirement Overview'!C:C,'Requirement Overview'!E:E)) -> Talme | E2: IT | F2: =IF(ISBLANK(A2),"",_xlfn.XLOOKUP(A2,'Requirement Overview'!C:C,'Requirement Overview'!I:I)) -> Android BSP Developer | G2: KPIT | H2: DINESHKUMAR S | K2: 6383142221 | M2: 5.11 | O2: 12 | R2: 18 | S2: Screening Reject | T2: Portal-Naukri | U2: 46028 | V2: 46028
A3: B001 | B3: R004 | C3: Pooja | D3: Talme | E3: =IF(ISBLANK(A3),"",_xlfn.XLOOKUP(A3,'Requirement Overview'!C:C,'Requirement Overview'!H:H)) -> IT | F3: =IF(ISBLANK(A3),"",_xlfn.XLOOKUP(A3,'Requirement Overview'!C:C,'Requirement Overview'!I:I)) -> Android BSP Developer | G3: KPIT | H3: Siva Raj Mahendrakar | K3: 9985736277 | S3: Screening Reject | T3: Portal-Naukri | U3: 46028 | V3: 46028
A4: B001 | B4: R004 | C4: Pooja | D4: Talme | E4: =IF(ISBLANK(A4),"",_xlfn.XLOOKUP(A4,'Requirement Overview'!C:C,'Requirement Overview'!H:H)) -> IT | F4: =IF(ISBLANK(A4),"",_xlfn.XLOOKUP(A4,'Requirement Overview'!C:C,'Requirement Overview'!I:I)) -> Android BSP Developer | G4: KPIT | H4: K Mallikarjuna Rao | J4: malli.k1117@gmail.com | K4: 9642601689 | M4: 6.8 | O4: 23 | R4: 30% Hike | S4: Screening Reject | T4: Portal-Naukri | U4: 46028 | V4: 46028
A5: B001 | B5: R004 | C5: Pooja | D5: Talme | E5: =IF(ISBLANK(A5),"",_xlfn.XLOOKUP(A5,'Requirement Overview'!C:C,'Requirement Overview'!H:H)) -> IT | F5: =IF(ISBLANK(A5),"",_xlfn.XLOOKUP(A5,'Requirement Overview'!C:C,'Requirement Overview'!I:I)) -> Android BSP Developer | G5: KPIT | H5: Gopi Vagga | K5: 9845892797 | M5: 12 | O5: 18.5 | R5: 25 | S5: Screening Reject | T5: Portal-Naukri | U5: 46028 | V5: 46028
A6: B001 | B6: R004 | C6: Pooja | D6: Talme | E6: =IF(ISBLANK(A6),"",_xlfn.XLOOKUP(A6,'Requirement Overview'!C:C,'Requirement Overview'!H:H)) -> IT | F6: =IF(ISBLANK(A6),"",_xlfn.XLOOKUP(A6,'Requirement Overview'!C:C,'Requirement Overview'!I:I)) -> Android BSP Developer | G6: KPIT | H6: Priyankka K | K6: 9618943124 | M6: 10.8 | O6: 22.5 | R6: 32 | S6: Screening Reject | T6: Portal-Naukri | U6: 46028 | V6: 46028
A7: B001 | B7: R004 | C7: Pooja | D7: Talme | E7: =IF(ISBLANK(A7),"",_xlfn.XLOOKUP(A7,'Requirement Overview'!C:C,'Requirement Overview'!H:H)) -> IT | F7: =IF(ISBLANK(A7),"",_xlfn.XLOOKUP(A7,'Requirement Overview'!C:C,'Requirement Overview'!I:I)) -> Android BSP Developer | G7: KPIT | H7: Tanmay Desai | K7: 7567041466 | S7: Screening Reject | T7: Portal-Naukri | U7: 46028 | V7: 46028
A8: B001 | B8: R004 | C8: =IF(ISBLANK(B8),"",_xlfn.XLOOKUP(B8,Recruiter!A:A,Recruiter!B:B)) -> Pooja | D8: Talme | E8: =IF(ISBLANK(A8),"",_xlfn.XLOOKUP(A8,'Requirement Overview'!C:C,'Requirement Overview'!H:H)) -> IT | F8: =IF(ISBLANK(A8),"",_xlfn.XLOOKUP(A8,'Requirement Overview'!C:C,'Requirement Overview'!I:I)) -> Android BSP Developer | G8: KPIT | H8: Mohamed musthafa AV | K8: 9895080216 | S8: Screening Reject | T8: Portal-Naukri | U8: 46029 | V8: 46029
A9: B001 | B9: R004 | C9: =IF(ISBLANK(B9),"",_xlfn.XLOOKUP(B9,Recruiter!A:A,Recruiter!B:B)) -> Pooja | D9: Talme | E9: =IF(ISBLANK(A9),"",_xlfn.XLOOKUP(A9,'Requirement Overview'!C:C,'Requirement Overview'!H:H)) -> IT | F9: =IF(ISBLANK(A9),"",_xlfn.XLOOKUP(A9,'Requirement Overview'!C:C,'Requirement Overview'!I:I)) -> Android BSP Developer | G9: KPIT | H9: Manikandan R | K9: 9500383529 | S9: Screening Reject | T9: Portal-Naukri | U9: 46029 | V9: 46029
A10: B001 | B10: R004 | C10: =IF(ISBLANK(B10),"",_xlfn.XLOOKUP(B10,Recruiter!A:A,Recruiter!B:B)) -> Pooja | D10: Talme | E10: =IF(ISBLANK(A10),"",_xlfn.XLOOKUP(A10,'Requirement Overview'!C:C,'Requirement Overview'!H:H)) -> IT | F10: =IF(ISBLANK(A10),"",_xlfn.XLOOKUP(A10,'Requirement Overview'!C:C,'Requirement Overview'!I:I)) -> Android BSP Developer | G10: KPIT | H10: Lavhate Pranav Pralhad | K10: 9021483838 | S10: Screening Reject | T10: Portal-Naukri | U10: 46029 | V10: 46029
A11: B001 | B11: R004 | C11: =IF(ISBLANK(B11),"",_xlfn.XLOOKUP(B11,Recruiter!A:A,Recruiter!B:B)) -> Pooja | D11: Talme | E11: =IF(ISBLANK(A11),"",_xlfn.XLOOKUP(A11,'Requirement Overview'!C:C,'Requirement Overview'!H:H)) -> IT | F11: =IF(ISBLANK(A11),"",_xlfn.XLOOKUP(A11,'Requirement Overview'!C:C,'Requirement Overview'!I:I)) -> Android BSP Developer | G11: KPIT | H11: Mayur Barapatre | J11: mayur04barapatre@gmail.com | K11: 6281643063 | O11: 20 | R11: 28 | S11: Screening Reject | T11: Portal-Naukri | U11: 46029 | V11: 46029
A12: B001 | B12: R004 | C12: =IF(ISBLANK(B12),"",_xlfn.XLOOKUP(B12,Recruiter!A:A,Recruiter!B:B)) -> Pooja | D12: Talme | E12: =IF(ISBLANK(A12),"",_xlfn.XLOOKUP(A12,'Requirement Overview'!C:C,'Requirement Overview'!H:H)) -> IT | F12: =IF(ISBLANK(A12),"",_xlfn.XLOOKUP(A12,'Requirement Overview'!C:C,'Requirement Overview'!I:I)) -> Android BSP Developer | G12: KPIT | H12: Naveen kumar | K12: 7981241891 | S12: Screening Reject | T12: Portal-Naukri | U12: 46029 | V12: 46029
A13: B001 | B13: R004 | C13: =IF(ISBLANK(B13),"",_xlfn.XLOOKUP(B13,Recruiter!A:A,Recruiter!B:B)) -> Pooja | D13: Talme | E13: =IF(ISBLANK(A13),"",_xlfn.XLOOKUP(A13,'Requirement Overview'!C:C,'Requirement Overview'!H:H)) -> IT | F13: =IF(ISBLANK(A13),"",_xlfn.XLOOKUP(A13,'Requirement Overview'!C:C,'Requirement Overview'!I:I)) -> Android BSP Developer | G13: KPIT | H13: Naveen Raj | J13: naveenraj5341@gmail.com | K13: 9400603341 | O13: 26.7 | R13: 36 | S13: Screening Reject | T13: Portal-Naukri | U13: 46029 | V13: 46029
A14: B001 | B14: R004 | C14: =IF(ISBLANK(B14),"",_xlfn.XLOOKUP(B14,Recruiter!A:A,Recruiter!B:B)) -> Pooja | D14: Talme | E14: =IF(ISBLANK(A14),"",_xlfn.XLOOKUP(A14,'Requirement Overview'!C:C,'Requirement Overview'!H:H)) -> IT | F14: =IF(ISBLANK(A14),"",_xlfn.XLOOKUP(A14,'Requirement Overview'!C:C,'Requirement Overview'!I:I)) -> Android BSP Developer | G14: KPIT | H14: Vrushabh Rangraoji Motghare | K14: 9689959406 | S14: Screening Reject | T14: Portal-Naukri | U14: 46029 | V14: 46029
A15: B001 | B15: R004 | C15: =IF(ISBLANK(B15),"",_xlfn.XLOOKUP(B15,Recruiter!A:A,Recruiter!B:B)) -> Pooja | D15: =IF(ISBLANK(A15),"",_xlfn.XLOOKUP(A15,'Requirement Overview'!C:C,'Requirement Overview'!E:E)) -> Talme | E15: IT | F15: =IF(ISBLANK(A15),"",_xlfn.XLOOKUP(A15,'Requirement Overview'!C:C,'Requirement Overview'!I:I)) -> Android BSP Developer | G15: =IF(ISBLANK(A15),"",_xlfn.XLOOKUP(A15,'Requirement Overview'!C:C,'Requirement Overview'!G:G)) -> KPIT | H15: Mosin Inamadar | K15: 9767204706 | S15: Screening Reject | T15: Portal-Naukri | U15: 46029 | V15: 46029
A16: H001 | B16: R003 | C16: Bhoomika | D16: =IF(ISBLANK(A16),"",_xlfn.XLOOKUP(A16,'Requirement Overview'!C:C,'Requirement Overview'!E:E)) -> Talme | E16: =IF(ISBLANK(A16),"",_xlfn.XLOOKUP(A16,'Requirement Overview'!C:C,'Requirement Overview'!H:H)) -> Non - IT | F16: =IF(ISBLANK(A16),"",_xlfn.XLOOKUP(A16,'Requirement Overview'!C:C,'Requirement Overview'!I:I)) -> Business developement executive | G16: Saralx | H16: Alefiyah Naib | I16: 30 Days | J16: alefiyahnaib515253@gmail.com | K16: 9179265452 | L16: B.ED | M16: 1.5 Years | N16: GIT Academy, Bengaluru | O16: 2.9 LPA | P16: Bengaluru | Q16: Bengaluru | R16: 3.9 LPA | S16: Screening Reject by Client | T16: Portal-LinkedIN | U16: 46029 | V16: 46029
A17: H001 | B17: R003 | C17: Bhoomika | D17: =IF(ISBLANK(A17),"",_xlfn.XLOOKUP(A17,'Requirement Overview'!C:C,'Requirement Overview'!E:E)) -> Talme | E17: =IF(ISBLANK(A17),"",_xlfn.XLOOKUP(A17,'Requirement Overview'!C:C,'Requirement Overview'!H:H)) -> Non - IT | F17: =IF(ISBLANK(A17),"",_xlfn.XLOOKUP(A17,'Requirement Overview'!C:C,'Requirement Overview'!I:I)) -> Business developement executive | G17: Saralx | H17: Ranjitha N | K17: 9535544283 | S17: Screening Reject | T17: Portal-LinkedIN | U17: 46028 | V17: 46028
A18: H001 | B18: R003 | C18: Bhoomika | D18: =IF(ISBLANK(A18),"",_xlfn.XLOOKUP(A18,'Requirement Overview'!C:C,'Requirement Overview'!E:E)) -> Talme | E18: =IF(ISBLANK(A18),"",_xlfn.XLOOKUP(A18,'Requirement Overview'!C:C,'Requirement Overview'!H:H)) -> Non - IT | F18: =IF(ISBLANK(A18),"",_xlfn.XLOOKUP(A18,'Requirement Overview'!C:C,'Requirement Overview'!I:I)) -> Business developement executive | G18: Saralx | H18: Dimpu B | K18: 9535735939 | S18: Screening Reject | T18: Portal-LinkedIN | U18: 46028 | V18: 46028
A19: H001 | B19: R003 | C19: Bhoomika | D19: =IF(ISBLANK(A19),"",_xlfn.XLOOKUP(A19,'Requirement Overview'!C:C,'Requirement Overview'!E:E)) -> Talme | E19: =IF(ISBLANK(A19),"",_xlfn.XLOOKUP(A19,'Requirement Overview'!C:C,'Requirement Overview'!H:H)) -> Non - IT | F19: =IF(ISBLANK(A19),"",_xlfn.XLOOKUP(A19,'Requirement Overview'!C:C,'Requirement Overview'!I:I)) -> Business developement executive | G19: Saralx | H19: Niveditha S | K19: 7760182939 | S19: Screening Reject | T19: Portal-LinkedIN | U19: 46028 | V19: 46028
A20: H001 | B20: R003 | C20: Bhoomika | D20: =IF(ISBLANK(A20),"",_xlfn.XLOOKUP(A20,'Requirement Overview'!C:C,'Requirement Overview'!E:E)) -> Talme | E20: =IF(ISBLANK(A20),"",_xlfn.XLOOKUP(A20,'Requirement Overview'!C:C,'Requirement Overview'!H:H)) -> Non - IT | F20: =IF(ISBLANK(A20),"",_xlfn.XLOOKUP(A20,'Requirement Overview'!C:C,'Requirement Overview'!I:I)) -> Business developement executive | G20: Saralx | H20: Dileep Kumar R | K20: 6364919558 | S20: Screening Reject | T20: Portal-LinkedIN | U20: 46028 | V20: 46028
A21: H001 | B21: R003 | C21: Bhoomika | D21: =IF(ISBLANK(A21),"",_xlfn.XLOOKUP(A21,'Requirement Overview'!C:C,'Requirement Overview'!E:E)) -> Talme | E21: =IF(ISBLANK(A21),"",_xlfn.XLOOKUP(A21,'Requirement Overview'!C:C,'Requirement Overview'!H:H)) -> Non - IT | F21: =IF(ISBLANK(A21),"",_xlfn.XLOOKUP(A21,'Requirement Overview'!C:C,'Requirement Overview'!I:I)) -> Business developement executive | G21: Saralx | H21: Harshita Khanna | K21: 8860765049 | S21: Screening Reject | T21: Portal-LinkedIN | U21: 46028 | V21: 46028
A22: H001 | B22: R003 | C22: Bhoomika | D22: =IF(ISBLANK(A22),"",_xlfn.XLOOKUP(A22,'Requirement Overview'!C:C,'Requirement Overview'!E:E)) -> Talme | E22: =IF(ISBLANK(A22),"",_xlfn.XLOOKUP(A22,'Requirement Overview'!C:C,'Requirement Overview'!H:H)) -> Non - IT | F22: =IF(ISBLANK(A22),"",_xlfn.XLOOKUP(A22,'Requirement Overview'!C:C,'Requirement Overview'!I:I)) -> Business developement executive | G22: Saralx | H22: Nitish Kumar | K22: 6362554577 | S22: Screening Reject | T22: Portal-LinkedIN | U22: 46028 | V22: 46028
A23: H002 | B23: R003 | C23: =IF(ISBLANK(B23),"",_xlfn.XLOOKUP(B23,Recruiter!A:A,Recruiter!B:B)) -> Bhoomika | D23: =IF(ISBLANK(A23),"",_xlfn.XLOOKUP(A23,'Requirement Overview'!C:C,'Requirement Overview'!E:E)) -> Talme | E23: =IF(ISBLANK(A23),"",_xlfn.XLOOKUP(A23,'Requirement Overview'!C:C,'Requirement Overview'!H:H)) -> Non - IT | F23: =IF(ISBLANK(A23),"",_xlfn.XLOOKUP(A23,'Requirement Overview'!C:C,'Requirement Overview'!I:I)) -> Founder office assoicate | G23: Saralx | H23: Shivam Asthana | K23: 6387986418 | M23: 4 Years | O23: 6.24 LPA | R23: 8 lpa | S23: Screening Reject | T23: Portal-LinkedIN | U23: 46027 | V23: 46027
A24: E001 | B24: R004 | C24: =IF(ISBLANK(B24),"",_xlfn.XLOOKUP(B24,Recruiter!A:A,Recruiter!B:B)) -> Pooja | D24: =IF(ISBLANK(A24),"",_xlfn.XLOOKUP(A24,'Requirement Overview'!C:C,'Requirement Overview'!E:E)) -> Talme | E24: =IF(ISBLANK(A24),"",_xlfn.XLOOKUP(A24,'Requirement Overview'!C:C,'Requirement Overview'!H:H)) -> Non - IT | F24: =IF(ISBLANK(A24),"",_xlfn.XLOOKUP(A24,'Requirement Overview'!C:C,'Requirement Overview'!I:I)) -> Graphic Designer | G24: =IF(ISBLANK(A24),"",_xlfn.XLOOKUP(A24,'Requirement Overview'!C:C,'Requirement Overview'!G:G)) -> Avinashi Ads | H24: HARINI YEJJU | J24: yejjuharini42@gmail.com | K24: 9392779274 | S24: Screening Reject | T24: Portal-LinkedIN | U24: 46030 | V24: 46030
A25: E001 | B25: R004 | C25: =IF(ISBLANK(B25),"",_xlfn.XLOOKUP(B25,Recruiter!A:A,Recruiter!B:B)) -> Pooja | D25: =IF(ISBLANK(A25),"",_xlfn.XLOOKUP(A25,'Requirement Overview'!C:C,'Requirement Overview'!E:E)) -> Talme | E25: =IF(ISBLANK(A25),"",_xlfn.XLOOKUP(A25,'Requirement Overview'!C:C,'Requirement Overview'!H:H)) -> Non - IT | F25: =IF(ISBLANK(A25),"",_xlfn.XLOOKUP(A25,'Requirement Overview'!C:C,'Requirement Overview'!I:I)) -> Graphic Designer | G25: =IF(ISBLANK(A25),"",_xlfn.XLOOKUP(A25,'Requirement Overview'!C:C,'Requirement Overview'!G:G)) -> Avinashi Ads | H25: SHRUTI RAI | J25: shrutirai.770@gmail.com | K25: 7704078279 | S25: Screening Reject | T25: Portal-LinkedIN | U25: 46030 | V25: 46030
A26: E001 | B26: R004 | C26: =IF(ISBLANK(B26),"",_xlfn.XLOOKUP(B26,Recruiter!A:A,Recruiter!B:B)) -> Pooja | D26: =IF(ISBLANK(A26),"",_xlfn.XLOOKUP(A26,'Requirement Overview'!C:C,'Requirement Overview'!E:E)) -> Talme | E26: =IF(ISBLANK(A26),"",_xlfn.XLOOKUP(A26,'Requirement Overview'!C:C,'Requirement Overview'!H:H)) -> Non - IT | F26: =IF(ISBLANK(A26),"",_xlfn.XLOOKUP(A26,'Requirement Overview'!C:C,'Requirement Overview'!I:I)) -> Graphic Designer | G26: =IF(ISBLANK(A26),"",_xlfn.XLOOKUP(A26,'Requirement Overview'!C:C,'Requirement Overview'!G:G)) -> Avinashi Ads | H26: Pranathi M.G | J26: pranathigopal00@gmail.com | K26: 8660746114 | S26: Screening Reject | T26: Portal-LinkedIN | U26: 46030 | V26: 46030
A27: D001 | B27: R003 | C27: =IF(ISBLANK(B27),"",_xlfn.XLOOKUP(B27,Recruiter!A:A,Recruiter!B:B)) -> Bhoomika | D27: =IF(ISBLANK(A27),"",_xlfn.XLOOKUP(A27,'Requirement Overview'!C:C,'Requirement Overview'!E:E)) -> Talme | E27: =IF(ISBLANK(A27),"",_xlfn.XLOOKUP(A27,'Requirement Overview'!C:C,'Requirement Overview'!H:H)) -> Non - IT | F27: =IF(ISBLANK(A27),"",_xlfn.XLOOKUP(A27,'Requirement Overview'!C:C,'Requirement Overview'!I:I)) -> Inside Sales Executive | G27: =IF(ISBLANK(A27),"",_xlfn.XLOOKUP(A27,'Requirement Overview'!C:C,'Requirement Overview'!G:G)) -> Peritas | H27: Saloni Sing | I27: 30 Days | J27: salonisingh0877@gmail.com | K27: 6377429482 | L27: MBA | M27: 1.3 Years | N27: Panchami Global Project Pvt Ltd | O27: 2.8 LPA | P27: Bengaluru | Q27: Bengaluru | R27: 3.5 LPA | S27: Screening Reject by Client | T27: Portal-Naukri | U27: 46029 | V27: 46029
A28: D001 | B28: R003 | C28: =IF(ISBLANK(B28),"",_xlfn.XLOOKUP(B28,Recruiter!A:A,Recruiter!B:B)) -> Bhoomika | D28: =IF(ISBLANK(A28),"",_xlfn.XLOOKUP(A28,'Requirement Overview'!C:C,'Requirement Overview'!E:E)) -> Talme | E28: =IF(ISBLANK(A28),"",_xlfn.XLOOKUP(A28,'Requirement Overview'!C:C,'Requirement Overview'!H:H)) -> Non - IT | F28: =IF(ISBLANK(A28),"",_xlfn.XLOOKUP(A28,'Requirement Overview'!C:C,'Requirement Overview'!I:I)) -> Inside Sales Executive | G28: =IF(ISBLANK(A28),"",_xlfn.XLOOKUP(A28,'Requirement Overview'!C:C,'Requirement Overview'!G:G)) -> Peritas | H28: Ashwin N R | I28: 7 Days | J28: dhanyahari878@gmail.com | K28: 7483352201 | L28: P.G.D.C.A | M28: 1.5 Years | N28: Mobility Motors | O28: 2.8 LPA | P28: Bengaluru | Q28: Bengaluru | R28: 3.2 LPA | S28: Screening Reject by Client | T28: Portal-Naukri | U28: 46029 | V28: 46029
A29: D001 | B29: R003 | C29: =IF(ISBLANK(B29),"",_xlfn.XLOOKUP(B29,Recruiter!A:A,Recruiter!B:B)) -> Bhoomika | D29: =IF(ISBLANK(A29),"",_xlfn.XLOOKUP(A29,'Requirement Overview'!C:C,'Requirement Overview'!E:E)) -> Talme | E29: =IF(ISBLANK(A29),"",_xlfn.XLOOKUP(A29,'Requirement Overview'!C:C,'Requirement Overview'!H:H)) -> Non - IT | F29: =IF(ISBLANK(A29),"",_xlfn.XLOOKUP(A29,'Requirement Overview'!C:C,'Requirement Overview'!I:I)) -> Inside Sales Executive | G29: =IF(ISBLANK(A29),"",_xlfn.XLOOKUP(A29,'Requirement Overview'!C:C,'Requirement Overview'!G:G)) -> Peritas | H29: Parul Vishwakarma | I29: 10 Days | J29: parulvishwakarma2020@gmail.com | K29: 8918605535 | L29: B.Tech | M29: 2 Years | N29: Inosystek Solutions Pvt. Ltd | O29: 3.9 LPA | P29: Bengaluru | Q29: Bengaluru | R29: 30% HIKE | S29: Screening Reject by Client | T29: Portal-Naukri | U29: 46029 | V29: 46029
A30: D001 | B30: R003 | C30: =IF(ISBLANK(B30),"",_xlfn.XLOOKUP(B30,Recruiter!A:A,Recruiter!B:B)) -> Bhoomika | D30: =IF(ISBLANK(A30),"",_xlfn.XLOOKUP(A30,'Requirement Overview'!C:C,'Requirement Overview'!E:E)) -> Talme | E30: =IF(ISBLANK(A30),"",_xlfn.XLOOKUP(A30,'Requirement Overview'!C:C,'Requirement Overview'!H:H)) -> Non - IT | F30: =IF(ISBLANK(A30),"",_xlfn.XLOOKUP(A30,'Requirement Overview'!C:C,'Requirement Overview'!I:I)) -> Inside Sales Executive | G30: =IF(ISBLANK(A30),"",_xlfn.XLOOKUP(A30,'Requirement Overview'!C:C,'Requirement Overview'!G:G)) -> Peritas | H30: Vidhya M Sank | I30: 7 Days | J30: vidyasank2003@gmail.com | K30: 9535796270 | L30: B.E | M30: 6 Months | N30: Simpliaxis Solutions Private Ltd | O30: 2.5 LPA | P30: Bengaluru | Q30: Bengaluru | R30: 3.5 LPA | S30: Screening Reject by Client | T30: Portal-Naukri | U30: 46029 | V30: 46029
A31: D001 | B31: R003 | C31: =IF(ISBLANK(B31),"",_xlfn.XLOOKUP(B31,Recruiter!A:A,Recruiter!B:B)) -> Bhoomika | D31: =IF(ISBLANK(A31),"",_xlfn.XLOOKUP(A31,'Requirement Overview'!C:C,'Requirement Overview'!E:E)) -> Talme | E31: =IF(ISBLANK(A31),"",_xlfn.XLOOKUP(A31,'Requirement Overview'!C:C,'Requirement Overview'!H:H)) -> Non - IT | F31: =IF(ISBLANK(A31),"",_xlfn.XLOOKUP(A31,'Requirement Overview'!C:C,'Requirement Overview'!I:I)) -> Inside Sales Executive | G31: =IF(ISBLANK(A31),"",_xlfn.XLOOKUP(A31,'Requirement Overview'!C:C,'Requirement Overview'!G:G)) -> Peritas | H31: Madiha Yasmeen | I31: Immediately | J31: yasmeenmadiha524@gmail.com | K31: 9880711626 | L31: PUC | M31: 4 Months | N31: Info technology company | O31: 2 LPA | P31: Bengaluru | Q31: Bengaluru | R31: 3.5 LPA | S31: Screening Reject by Client | T31: Portal-Naukri | U31: 46030 | V31: 46030
A32: D001 | B32: R003 | C32: =IF(ISBLANK(B32),"",_xlfn.XLOOKUP(B32,Recruiter!A:A,Recruiter!B:B)) -> Bhoomika | D32: =IF(ISBLANK(A32),"",_xlfn.XLOOKUP(A32,'Requirement Overview'!C:C,'Requirement Overview'!E:E)) -> Talme | E32: =IF(ISBLANK(A32),"",_xlfn.XLOOKUP(A32,'Requirement Overview'!C:C,'Requirement Overview'!H:H)) -> Non - IT | F32: =IF(ISBLANK(A32),"",_xlfn.XLOOKUP(A32,'Requirement Overview'!C:C,'Requirement Overview'!I:I)) -> Inside Sales Executive | G32: =IF(ISBLANK(A32),"",_xlfn.XLOOKUP(A32,'Requirement Overview'!C:C,'Requirement Overview'!G:G)) -> Peritas | H32: Farha Anjum | I32: Immediately | J32: ammuanjum136@gmail.com | K32: 9380875136 | L32: PUC | M32: 4 Years( Telesales) | N32: Blackbuck | O32: 2.5 LPA | P32: Chikkabanavara | Q32: Bengaluru | R32: 3 LPA | S32: Screening Reject by Client | T32: Portal-LinkedIN | U32: 46030 | V32: 46030
A33: D002 | B33: R003 | C33: =IF(ISBLANK(B33),"",_xlfn.XLOOKUP(B33,Recruiter!A:A,Recruiter!B:B)) -> Bhoomika | D33: =IF(ISBLANK(A33),"",_xlfn.XLOOKUP(A33,'Requirement Overview'!C:C,'Requirement Overview'!E:E)) -> Talme | E33: =IF(ISBLANK(A33),"",_xlfn.XLOOKUP(A33,'Requirement Overview'!C:C,'Requirement Overview'!H:H)) -> Non - IT | F33: =IF(ISBLANK(A33),"",_xlfn.XLOOKUP(A33,'Requirement Overview'!C:C,'Requirement Overview'!I:I)) -> Field Sales Executive | G33: =IF(ISBLANK(A33),"",_xlfn.XLOOKUP(A33,'Requirement Overview'!C:C,'Requirement Overview'!G:G)) -> Peritas | H33: Girish | I33: Immediately | J33: girishdivakar04@gmail.com | K33: 9740531518 | L33: B.Com | M33: 2 Years ( Telesales) | N33: Innovative System Pvt Ltd | O33: 2.7 LPA | P33: Bengaluru | Q33: Bengaluru | R33: 3 LPA | S33: Screening Reject by Client | T33: Portal-LinkedIN | U33: 46030 | V33: 46030
A34: D002 | B34: R003 | C34: =IF(ISBLANK(B34),"",_xlfn.XLOOKUP(B34,Recruiter!A:A,Recruiter!B:B)) -> Bhoomika | D34: =IF(ISBLANK(A34),"",_xlfn.XLOOKUP(A34,'Requirement Overview'!C:C,'Requirement Overview'!E:E)) -> Talme | E34: =IF(ISBLANK(A34),"",_xlfn.XLOOKUP(A34,'Requirement Overview'!C:C,'Requirement Overview'!H:H)) -> Non - IT | F34: =IF(ISBLANK(A34),"",_xlfn.XLOOKUP(A34,'Requirement Overview'!C:C,'Requirement Overview'!I:I)) -> Field Sales Executive | G34: =IF(ISBLANK(A34),"",_xlfn.XLOOKUP(A34,'Requirement Overview'!C:C,'Requirement Overview'!G:G)) -> Peritas | H34: Jagannath G | I34: Immediately | J34: mailsforjagan44@gmail.com | K34: 90719 53498 | L34: PUC | M34: 3 Years ( Sales consltunt) | N34: Magic bricks | O34: 3.2 LPA | P34: Bengaluru | Q34: Bengaluru | R34: As per company standards | S34: Screening Reject by Client | T34: Portal-LinkedIN | U34: 46030 | V34: 46030
A35: A003 | B35: R002 | C35: =IF(ISBLANK(B35),"",_xlfn.XLOOKUP(B35,Recruiter!A:A,Recruiter!B:B)) -> Harshitha | D35: =IF(ISBLANK(A35),"",_xlfn.XLOOKUP(A35,'Requirement Overview'!C:C,'Requirement Overview'!E:E)) -> Talme | E35: =IF(ISBLANK(A35),"",_xlfn.XLOOKUP(A35,'Requirement Overview'!C:C,'Requirement Overview'!H:H)) -> IT | F35: =IF(ISBLANK(A35),"",_xlfn.XLOOKUP(A35,'Requirement Overview'!C:C,'Requirement Overview'!I:I)) -> Python Architect | G35: =IF(ISBLANK(A35),"",_xlfn.XLOOKUP(A35,'Requirement Overview'!C:C,'Requirement Overview'!G:G)) -> EMIDS | H35: Sandeep Kumar | I35: Immediately | J35: sandy20mjn@gmail.com | K35: 9456903676 | L35: B.Tech | M35: 14 Years | N35: Bitwise Solutions | O35: 40 LPA | R35: 48 LPA | S35: Screening Reject by Client | T35: Portal-Naukri | U35: 46030 | V35: 46030 | W35: Rejected by panel
A36: A003 | B36: R002 | C36: =IF(ISBLANK(B36),"",_xlfn.XLOOKUP(B36,Recruiter!A:A,Recruiter!B:B)) -> Harshitha | D36: =IF(ISBLANK(A36),"",_xlfn.XLOOKUP(A36,'Requirement Overview'!C:C,'Requirement Overview'!E:E)) -> Talme | E36: =IF(ISBLANK(A36),"",_xlfn.XLOOKUP(A36,'Requirement Overview'!C:C,'Requirement Overview'!H:H)) -> IT | F36: =IF(ISBLANK(A36),"",_xlfn.XLOOKUP(A36,'Requirement Overview'!C:C,'Requirement Overview'!I:I)) -> Python Architect | G36: =IF(ISBLANK(A36),"",_xlfn.XLOOKUP(A36,'Requirement Overview'!C:C,'Requirement Overview'!G:G)) -> EMIDS | H36: rajesh kumar | J36: rajesh7733@gmail.com | K36: 9900297636 | L36: M.Tech | M36: 10 Years | N36: Continental Automotive | O36: 30 LPA | R36: 40 LPA | S36: Screening Reject by Client | T36: Portal-Naukri | U36: 46030 | V36: 46030 | W36: Rejected by panel
A37: A003 | B37: R002 | C37: =IF(ISBLANK(B37),"",_xlfn.XLOOKUP(B37,Recruiter!A:A,Recruiter!B:B)) -> Harshitha | D37: =IF(ISBLANK(A37),"",_xlfn.XLOOKUP(A37,'Requirement Overview'!C:C,'Requirement Overview'!E:E)) -> Talme | E37: =IF(ISBLANK(A37),"",_xlfn.XLOOKUP(A37,'Requirement Overview'!C:C,'Requirement Overview'!H:H)) -> IT | F37: =IF(ISBLANK(A37),"",_xlfn.XLOOKUP(A37,'Requirement Overview'!C:C,'Requirement Overview'!I:I)) -> Python Architect | G37: =IF(ISBLANK(A37),"",_xlfn.XLOOKUP(A37,'Requirement Overview'!C:C,'Requirement Overview'!G:G)) -> EMIDS | H37: JOY MUKHERJEE BHUMANA | J37: joycloud77@gmail.com | K37: 8639873718 | L37: B.Tech | M37: 10.6 Years | N37: GENPACT | O37: 29 LPA | R37: 39 LPA | S37: Tech 1 Reject | T37: Portal-Naukri | U37: 46030 | V37: 46030 | W37: L1 scheduled | X37: 46037 | Y37: Reject
A38: A004 | B38: R002 | C38: =IF(ISBLANK(B38),"",_xlfn.XLOOKUP(B38,Recruiter!A:A,Recruiter!B:B)) -> Harshitha | D38: =IF(ISBLANK(A38),"",_xlfn.XLOOKUP(A38,'Requirement Overview'!C:C,'Requirement Overview'!E:E)) -> Talme | E38: =IF(ISBLANK(A38),"",_xlfn.XLOOKUP(A38,'Requirement Overview'!C:C,'Requirement Overview'!H:H)) -> IT | F38: =IF(ISBLANK(A38),"",_xlfn.XLOOKUP(A38,'Requirement Overview'!C:C,'Requirement Overview'!I:I)) -> Windows system adminstrator | G38: =IF(ISBLANK(A38),"",_xlfn.XLOOKUP(A38,'Requirement Overview'!C:C,'Requirement Overview'!G:G)) -> EMIDS | H38: Rakesh Kumar Mohapatra | J38: aapkarakesh46@gmail.com | K38: 7683937847 | L38: B.Tech | M38: 8 Years | N38: Skylink Communications | O38: 5 LPA | R38: 8 LPA | S38: Screening Reject | T38: Portal-Naukri | U38: 46030 | V38: 46030
A39: A004 | B39: R002 | C39: =IF(ISBLANK(B39),"",_xlfn.XLOOKUP(B39,Recruiter!A:A,Recruiter!B:B)) -> Harshitha | D39: =IF(ISBLANK(A39),"",_xlfn.XLOOKUP(A39,'Requirement Overview'!C:C,'Requirement Overview'!E:E)) -> Talme | E39: =IF(ISBLANK(A39),"",_xlfn.XLOOKUP(A39,'Requirement Overview'!C:C,'Requirement Overview'!H:H)) -> IT | F39: =IF(ISBLANK(A39),"",_xlfn.XLOOKUP(A39,'Requirement Overview'!C:C,'Requirement Overview'!I:I)) -> Windows system adminstrator | G39: =IF(ISBLANK(A39),"",_xlfn.XLOOKUP(A39,'Requirement Overview'!C:C,'Requirement Overview'!G:G)) -> EMIDS | H39: Saikumar | J39: saikumarsingathi31@gmail.com | K39: 9550345310 | L39: B.Tech | M39: 5.5 Years | N39: SMS TECHSOFT INDIA LIMITED | O39: 7.5 LPA | R39: 10 LPA | S39: Tech 1 to be Scheduled | T39: Portal-Naukri | U39: 46030 | V39: 46030
A40: A004 | B40: R002 | C40: =IF(ISBLANK(B40),"",_xlfn.XLOOKUP(B40,Recruiter!A:A,Recruiter!B:B)) -> Harshitha | D40: =IF(ISBLANK(A40),"",_xlfn.XLOOKUP(A40,'Requirement Overview'!C:C,'Requirement Overview'!E:E)) -> Talme | E40: =IF(ISBLANK(A40),"",_xlfn.XLOOKUP(A40,'Requirement Overview'!C:C,'Requirement Overview'!H:H)) -> IT | F40: =IF(ISBLANK(A40),"",_xlfn.XLOOKUP(A40,'Requirement Overview'!C:C,'Requirement Overview'!I:I)) -> Windows system adminstrator | G40: =IF(ISBLANK(A40),"",_xlfn.XLOOKUP(A40,'Requirement Overview'!C:C,'Requirement Overview'!G:G)) -> EMIDS | H40: Pushpendra singh | J40: pushpendrsingh41@gmail.com | K40: 7017152771 | L40: MCA | M40: 6 Years | N40: HCLTech | O40: 5.5 LPA | R40: 8.5 LPA | S40: Screening Reject | T40: Screening Reject | U40: 46030 | V40: 46030
...

Sheet Recruiter
A1: Recruiter ID | B1: Recruiter Name | C1: Email | D1: Phone Number | E1: Current Status | F1: Date of Joined | G1: LWD | H1: Designation
A2: R001 | B2: Harish | H2: HRBP
A3: R002 | B3: Harshitha | H3: Lead
A4: R003 | B4: Bhoomika | H4: Recruiter
A5: R004 | B5: Pooja | H5: Recruiter
A6: R005 | B6: Narthana | H6: Lead
A7: R006 | B7: Himanshu | H7: Recruiter
A8: R007 | B8: Pooja & Bhoomika

Sheet H. Role
A1: Position | B1: Harmonized Role
A2: Python Developer
A3: Lead Data Engineer
A4: Python Architect
A5: Windows system adminstrator
A6: Android BSP Developer
A7: Display driver
A8: Audio Driver
A9: Data Delivery Manager
A10: Senior IAM Operation Engineer
A11: Lead IAM Management
A12: PERL Developer
A13: Inside Sales Executive
... A26: Founder office assoicate

Sheet Performance Review
B2: Name | C2: No of Profiles as per Plan for the day | D2: No Of profile Shared | E2: Yet to receive feed back from panel | F2: No of profiles Screen Select | G2: No of Profiles rejected | H2: No of profiles in T1 | I2: T1 Rejected | L2: EMIDS | M2: ThoughtFocus | N2: Peritas | O2: Semnox | P2: Seralax | Q2: Inhouse | R2: KPIT | V2: Skill | W2: Open Positions | X2: Profiles
B3: Harshitha | C3: 75 | D3: 30 | E3: 5 | F3: 10 | G3: 20 | H3: 7 | I3: 3 | L3: 1. Windows sys - 18. 2. Python architech-13, | M3: 3.Lead Data - 5, DDM -2 | N3: Inside Sales - 2 | V3: Python Developer | W3: 2 | X3: Hold
B4: Bhoomika | C4: 75 | D4: 11 | E4: Nil | F4: 4 | G4: 7 | H4: 1 | I4: 2 | N4: Inside Sales - 5, Field - 2 | P4: BDE -2, | Q4: HR - 1 | U4: Emids | V4: Lead Data Engineer | W4: 4 | X4: Hold
B5: Pooja | C5: 60 | D5: 7 | E5: 2 | F5: 0 | G5: 5 | H5: 0 | I5: 0 | L5: Python Architect - 3 | R5: Android BSP - 4 | V5: Python Architect | W5: 1 | X5: 16
B6: Narthana | C6: 30 | D6: 7 | E6: 3 | F6: 0 | G6: 3 | H6: 0 | I6: 0 | L6: Winods system admin - 3 | R6: Android BSP - 4 | V6: Windows system adminstrator | W6: 1 | X6: 21
C7: =SUM(C3:C6) -> 240 | D7: =SUM(D3:D6) -> 55 | E7: =SUM(E3:E6) -> 10 | F7: =SUM(F3:F6) -> 14 | G7: =SUM(G3:G6) -> 35 | H7: =SUM(H3:H6) -> 8 | I7: =SUM(I3:I6) -> 5 | V7: Android BSP Developer | W7: 2 | X7: 8
C8: Naukri used- 321 | V8: Display driver | W8: 1 | X8: 0
V9: Audio Driver | W9: 1 | X9: 0
B15: Name | C15: No of Profiles as per Plan for the day | D15: No Of profile Shared | E15: Yet to receive feed back from panel | F15: No of profiles Screen Select | G15: No of Profiles rejected | H15: No of profiles in T1 | I15: T1 Rejected | L15: EMIDS | M15: ThoughtFocus | N15: Peritas | O15: Semnox | P15: Seralax | Q15: Inhouse | R15: KPIT | S15: Avinashi Ads
B16: Harshitha | C16: 20 | D16: 7 | E16: 4 | F16: 3 | H16: 3 | L16: 1. Windows sys - 3, Python architech-4
B17: Bhoomika | C17: 95 | D17: 25 | E17: 13 | F17: 5 | G17: 7 | H17: 4 | N17: Inside Sales - 6 | Q17: HR - 9 | S17: Graphic-2, Associate-1, KAM-4,Sales head-3
B18: Pooja | C18: 60 | D18: 20 | E18: 4 | F18: 1 | G18: 15 | H18: 0 | I18: 1 | M18: Lead data engineer-7 | S18: KAM-9, Associate sales-1, sales head-3
B19: Narthana | C19: 125 | D19: 19 | E19: 3 | F19: 5 | G19: 11 | H19: 5 | L19: Winods system admin - 17 | R19: Display driver-2
C20: =SUM(C16:C19) -> 300 | D20: =SUM(D16:D19) -> 71 | E20: =SUM(E16:E19) -> 24 | F20: =SUM(F16:F19) -> 14 | G20: =SUM(G16:G19) -> 33 | H20: =SUM(H16:H19) -> 12 | I20: =SUM(I16:I19) -> 1
B23: Name | C23: No of Profiles as per Plan for the day | D23: No Of profile Shared | E23: Yet to receive feed back from panel | F23: No of profiles Screen Select | G23: No of Profiles rejected | H23: No of profiles in T1 | I23: T1 Rejected | J23: IN T2 | K23: IN T3 | L23: EMIDS | M23: ThoughtFocus | N23: Peritas | O23: Semnox | P23: Seralax | Q23: Inhouse | R23: KPIT | S23: GNA | T23: Lead SOC | U23: Avinashi Ads
B24: Harshitha | C24: 80 | D24: 23 | E24: 3 | F24: 19 | G24: 3 | I24: 14 | J24: 1 | K24: 3 | L24: Wndows System - 5, Angular JS - 5, Python - 5 | M24: Lead Data engineer-3 | O24: .Net Dev -3 | T24: Angular RF Designer - 2
B25: Bhoomika | C25: 85 | D25: 23 | E25: 11 | G25: 6 | I25: 1 | L25: Angular JS - 6 | N25: Inside Sales - 7 | O25: Technical Lead Mobile -1 | U25: KAM - 4, Sales Head - 1, Associate Sales - 1, Graphic Designer -3
B26: Pooja | C26: 75 | D26: 31 | E26: 19 | G26: 4 | J26: 1 | L26: Angular JS - 4 | N26: Inside Sales - 3, Feild Sales -2 | O26: Technical Lead Mobile -1 | U26: Sales Head -11, GRaphic Designer -4, Associate Sales -2, KAM -1
B27: Narthana | C27: 85 | D27: 24 | E27: 5 | F27: 4 | H27: 2 | I27: 2 | L27: Windows system - 11, Python - 2 | M27: IAM Eng - 4. Lead IAM - 1 | O27: .Net Dev- 5 | S27: Block Chain Dev -1
C28: =SUM(C24:C27) -> 325 | D28: =SUM(D24:D27) -> 101 | E28: =SUM(E24:E27) -> 38 | F28: =SUM(F24:F27) -> 23 | G28: =SUM(G24:G27) -> 13 | H28: =SUM(H24:H27) -> 2 | I28: =SUM(I24:I27) -> 17
B34: RECRUITER | C34: REQUIREMENTS | D34: FROM 26-01-2026 TO 30-01-2026 | F34: Least No of Interviews should be scheduled in a day
B35: Harshitha | C35: EMIDS | D35: 3 Days | F35: Acheivable commitments
B36: Harshitha | C36: ThoughtFocus, KPIT, | F36: No of Profiles to be shared
B37: Pooja | C37: Vidita,Semnox, Peritas, Thoughtfocus
B38: Narthana | C38: ThoughtFocus, KPIT, Semnox, Peritas, EMIDS
B39: Bhoomika | C39: Vidita,Semnox, Peritas, Avinashi Ads
B42: Name | C42: No of Profiles as per Plan for the day | D42: No Of profile Shared | E42: Yet to receive feed back from panel | F42: No of profiles Screen Select | G42: No of Profiles rejected | H42: No of profiles in T1 | I42: T1 Rejected | J42: IN T2 | K42: IN T3 | L42: EMIDS | M42: ThoughtFocus | N42: Peritas | O42: Semnox | P42: Seralax | Q42: Inhouse | R42: KPIT | S42: Viditha | T42: Lead SOC | U42: Avinashi Ads
B43: Harshitha | C43: 60 | D43: 27 | E43: 6 | F43: 13 | G43: 8 | H43: 10 | I43: 2 | J43: 3 | L43: Java Sript -5, Python - 9, Angular JS- 1, Windows System -6 | M43: Java Lead support - 6
B44: Bhoomika | C44: 20 | D44: 18 | E44: 18 (Yet to share) | O44: .Net - 1 | S44: Full Stack Dev - 17
B45: Pooja | C45: 45 | D45: 18 | E45: 10 | N45: Inside Sales -7 | O45: .Net - 1 | S45: Full Stack Dev - 10
B46: Narthana | C46: 60 | D46: 24 | E46: 16 | G46: 3 | H46: 4 | J46: 1 | L46: Windows System -9, Python -2 | M46: Java Lead support - 2, IAM Eng-3, Senior IAM -1 | O46: Tech Lead -4 | S46: Full Stack Dev - 3
C47: =SUM(C43:C46) -> 185 | D47: =SUM(D43:D46) -> 87 | E47: =SUM(E43:E46) -> 32 | F47: =SUM(F43:F46) -> 13 | G47: =SUM(G43:G46) -> 11 | H47: =SUM(H43:H46) -> 14 | I47: =SUM(I43:I46) -> 2 | J47: =SUM(J43:J46) -> 4
B50: RECRUITER | C50: REQUIREMENTS, FROM 02-02-2026 TO 07-02-2026
B51: Harshitha | C51: EMIDS,ThoughtFocus, KPIT,GNA
B52: Pooja | C52: ,Semnox, Peritas, Thoughtfocus, GNA
B53: Narthana | C53: ThoughtFocus, KPIT, Semnox, GNA, EMIDS
B54: Bhoomika | C54: ,Semnox, Peritas, Avinashi Ads, GNA,
B57: Name | C57: No of Profiles as per Plan for the day | D57: No Of profile Shared | E57: Yet to receive feed back from panel | F57: No of profiles Screen Select | G57: No of Profiles rejected | H57: No of profiles in T1 | I57: T1 Rejected | J57: IN T2 | K57: IN T3 | L57: EMIDS | M57: ThoughtFocus | N57: Peritas | O57: Semnox | P57: GNA | Q57: KPIT | R57: Avinashi Ads
B58: Harshitha | C58: 40 | D58: 21 | E58: 8
B59: Bhoomika | C59: 55 | D59: 30 | H59: 2 | L59: Java Script - 6, Angular JS(1.7) - 2 | N59: Inside Sales- 10 | O59: Mobile Tech Lead -5 | P59: Full Stack Developer-5 | R59: Graphic Designer 1,Associate Sales -1
...

Sheet Sheet5
A1: Sl.No | B1: Client | C1: Domain | D1: Position | E1: Comments | F1: Years of EXp | G1: Location
A2: 1 | B2: KPIT | C2: IT | D2: Android BSP Developer
A3: 2 | B3: KPIT | C3: IT | D3: Display driver
A4: 3 | B4: KPIT | C4: IT | D4: Audio Driver
A5: 4 | B5: Thoughtfocus | C5: IT | D5: Lead Data Engineer
A6: 5 | B6: Thoughtfocus | C6: IT | D6: Senior IAM Operation Engineer | E6: Sayiant, Entra ID & Azzure ID (Mandate) Immediate NP | F6: 6-9 Years
A7: 6 | B7: Thoughtfocus | C7: IT | D7: Lead IAM Management | E7: Sayiant, Entra ID & Azzure ID (Mandate) Immediate NP | F7: 6-9 Years
A8: 7 | B8: Thoughtfocus | C8: IT | D8: IAM Engineer Professionals
A9: 8 | B9: Thoughtfocus | C9: IT | D9: Java Lead Analyst | E9: Java/Python (Payment, Banking domain) & End to end card trans, supporting L1 and L3 | F9: 5+ Years
A10: 9 | B10: Peritas | C10: Non - IT | D10: Inside Sales Executive | E10: Exp in IT sales | F10: 1-2 Years
A11: 10 | B11: Peritas | C11: Non - IT | D11: Field Sales Executive
A12: 11 | B12: Avinashi Ads | C12: Non - IT | D12: Graphic Designer | E12: Yet to receive feedbak from client
A13: 12 | B13: Avinashi Ads | C13: Non - IT | D13: Sales Head | E13: Yet to receive feedbak from client
A14: 13 | B14: Avinashi Ads | C14: Non - IT | D14: Senior Sales Manager | E14: Yet to receive feedbak from client
A15: 14 | B15: Avinashi Ads | C15: Non - IT | D15: Associate Sales | E15: Yet to receive feedbak from client
A16: 15 | B16: Avinashi Ads | C16: Non - IT | D16: Key Accounts Manager | E16: Yet to receive feedbak from client
A17: 16 | B17: GNA | C17: Non - IT | D17: Compliance Officer
A18: 17 | B18: GNA | C18: Non - IT | D18: Lobby In Charge
A19: 18 | B19: GNA | C19: IT | D19: QA Analyst | E19: Mandate (bnking Domain), Autoation Testing tool | F19: 2-4 Years
A20: 19 | B20: GNA | C20: IT | D20: Full Stack Developer | E20: Angular, Node js | F20: 2-4 Years
A21: 20 | B21: EMIDS | C21: IT | D21: Java Script Developer | E21: Java script, HTML , CSS | F21: 4-8 Years | G21: C2H
A22: 21 | B22: SBI Project | C22: IT | D22: Oracle | E22: Golden Gate, CDC Integration, Cloud Era Archi, Oracle RDBMS, (Banking Domain) | F22: 10 Years | G22: Mumbai Location | H22: 14 LPA
A23: 22 | B23: Brillio | C23: IT | E23: AI, Machie Learning, DDM's
A24: 23 | B24: LTTs | C24: IT

Sheet Dropdowns
A1: Tech Status | C1: Offer Status | E1: Offer Accept Status | G1: Source | I1: Recruiters | K1: Joining Status | M1: Candidate current status | P1: Business unit | R1: Department | T1: Client | V1: Domain | X1: Priority | Z1: Position Current Status | AB1: Position | AD1: Type of Hire
A2: Select | C2: Offered Yet to Join | E2: Offer Accepted | G2: Portal-Naukri | I2: Harish | K2: Joined | M2: Sourced | P2: Talme | T2: GNA | V2: IT | X2: High | Z2: Open | AB2: Data Delivery Manager | AD2: New
A3: Reject | C3: Doccument Collection | E3: Offer Rejected | G3: Portal-LinkedIN | I3: Harshitha | K3: No Show | M3: Yet to Screen | T3: Thoughtfocus | V3: IT | X3: Medium | Z3: Offered | AB3: Android BSP Developer | AD3: Replacement
A4: Hold | C4: Offer Drop | G4: Employee Reference | I4: Bhoomika | K4: Drop after Offer Accept | M4: Screening Reject by Client | T4: EMIDS | V4: IT | X4: Low | Z4: Offer Stage | AB4: Display driver
A5: No Show | C5: Offer Stage Drop | G5: Campus Drive | I5: Pooja | M5: Tech 1 to be Scheduled | T5: KPIT | V5: IT | Z5: Closed | AB5: Audio Driver
I6: Narthana | M6: Tech 1 Awaiting Feedback | T6: Talme | V6: IT | Z6: Hold | AB6: Sales Head
I7: Himanshu | M7: Tech 1 Reject | T7: Peritas | V7: Non - IT | AB7: Senior Sales Manager
I8: Pooja & Bhoomika | M8: Tech 2 to be Scheduled | T8: Avinashi Ads | V8: Non - IT | AB8: Key Accounts Manager
M9: Tech 2 Awaiting Feedback | T9: Sarelx | V9: Non - IT | AB9: Associate Sales
M10: Tech 2 Reject | T10: LeadSOC | V10: IT | AB10: Graphic Designer
M11: Tech 3 to be Scheduled | T11: Semnox Solutions | V11: IT | AB11: Data Engineer
M12: Tech 3 Awaiting Feedback | T12: Prasanna Technologies | V12: IT | AB12: Lead Data Engineer
M13: Tech 3 Reject | T13: Viditha | V13: IT | AB13: Python Developer
M14: Yet to Offer | T14: Anika Solutions | V14: IT | AB14: EDIPECS Developer
M15: Offer Released | T15: Megha foods pvt ltd | V15: Non - IT | AB15: Web Designer
M16: Doccument Collection | T16: L&T | V16: IT | AB16: Blockchain Developer
M17: Offer Accepted Yet to Join | T17: LTTS | V17: IT | AB17: Compliance Officer
M18: Offer Rejected | T18: Micron | V18: IT | AB18: Optiva PLM Functional Consultant
M19: Joined | AB19: Technical Project Manager
M20: No Show | AB20: Senior IAM Operation Engineer
M21: Screening reject by HR | AB21: Lead IAM Management
M22: Not Interested job change | AB22: PERL Developer
M23: Awaiting feedback from client | AB23: Python Architect
M24: position closed | AB24: Windows system adminstrator
M25: Position on Hold | AB25: Inside Sales Executive
AB26: Field Sales Executive
AB27: Wiring Technicians
AB28: Lobby In Charge
AB29: Lobby In Charge
AB30: Business developement executive
AB31: Founder office assoicate
AB32: HR Recruiter
AB33: Analog RF Designer
AB34: Angular JS developer
AB35: IAM Engineer Professionals
AB36: .Net Backend Developer
AB37: .Net Developer - Contract Role
... AB75: Software Engineer

Sheet Sheet1
A2: Client | B2: Years of Exp | C2: Count of Client
B3: (blank) | C3: 24
A4: Total | C4: 24
A5: Avinashi Ads | B5: (blank) | C5: 13
B6: 8 Year | C6: 5
B7: 6 Year | C7: 4
B8: 1 Year | C8: 3
B9: Fresher | C9: 3
B10: 7 Years | C10: 2
B11: 5 Year | C11: 2
B12: 4 Years | C12: 2
B13: 10 Year | C13: 2
B14: 6 Months( Internship) | C14: 2
B15: 1 Years | C15: 2
B16: 9 Years | C16: 2
B17: 8 Years | C17: 2
... B45: 2 Years | C45: 1
A46: Avinashi Ads Total | C46: 72
A47: EMIDS | B47: 5 Years | C47: 11
B48: 6 Years | C48: 11
B49: 7 Years | C49: 7
B50: 9 Years | C50: 4
B51: 11 Years | C51: 4
B52: 14 Years | C52: 3
B53: 7.5 Years | C53: 3
B54: 5.3 Years | C54: 2
B55: 6.8 Years | C55: 2
B56: 10 Years | C56: 2
B57: 4.4 Years | C57: 2
B58: 5.2 Years | C58: 2
B59: 6.9 Years | C59: 2
... B88: 4+ Years | C88: 1
A89: EMIDS Total | C89: 95
A90: GNA | B90: 6 Years | C90: 1
A91: GNA Total | C91: 1
A92: KPIT | B92: (blank) | C92: 7
C93: 3
B94: 8 Years | C94: 1
B95: 6.5 Years | C95: 1
B96: 6 Years | C96: 1
...

Sheet Sheet2
A2: Position | B2: Count of Job Id
A3: Windows system adminstrator | B3: 55
A4: Inside Sales Executive | B4: 31
A5: Sales Head | B5: 25
A6: Key Accounts Manager | B6: 21
A7: Angular JS developer | B7: 20
A8: Python Architect | B8: 20
A9: Android BSP Developer | B9: 18
A10: Graphic Designer | B10: 17
A11: HR Recruiter | B11: 16
A12: .Net Backend Developer | B12: 14
A13: Lead Data Engineer | B13: 13
A14: Business developement executive | B14: 12
... A28: Grand Total | B28: 295

Sheet Sheet3
A2: Client | B2: Count of Job Id
A3: EMIDS | B3: 95
A4: Avinashi Ads | B4: 72
A5: Peritas | B5: 36
A6: Thoughtfocus | B6: 23
A7: KPIT | B7: 20
A8: Semnox Solutions | B8: 16
A9: Talme | B9: 16
A10: Saralx | B10: 8
A11: Sarelx | B11: 6
A12: LeadSOC | B12: 2
A13: GNA | B13: 1
A15: Grand Total | B15: 295

Sheet Sheet4
